[2025-08-19T00:01:01.786+0000] {local_task_job_runner.py:123} INFO - ::group::Pre task execution logs
[2025-08-19T00:01:01.801+0000] {taskinstance.py:2612} INFO - Dependencies all met for dep_context=non-requeueable deps ti=<TaskInstance: dbt_workflow.dbt_run manual__2025-08-18T23:55:54.595255+00:00 [queued]>
[2025-08-19T00:01:01.807+0000] {taskinstance.py:2612} INFO - Dependencies all met for dep_context=requeueable deps ti=<TaskInstance: dbt_workflow.dbt_run manual__2025-08-18T23:55:54.595255+00:00 [queued]>
[2025-08-19T00:01:01.808+0000] {taskinstance.py:2865} INFO - Starting attempt 2 of 2
[2025-08-19T00:01:01.818+0000] {taskinstance.py:2888} INFO - Executing <Task(BashOperator): dbt_run> on 2025-08-18 23:55:54.595255+00:00
[2025-08-19T00:01:01.825+0000] {warnings.py:112} WARNING - /home/***/.local/lib/python3.12/site-packages/***/task/task_runner/standard_task_runner.py:70: DeprecationWarning: This process (pid=280) is multi-threaded, use of fork() may lead to deadlocks in the child.
  pid = os.fork()

[2025-08-19T00:01:01.828+0000] {standard_task_runner.py:72} INFO - Started process 282 to run task
[2025-08-19T00:01:01.827+0000] {standard_task_runner.py:104} INFO - Running: ['***', 'tasks', 'run', 'dbt_workflow', 'dbt_run', 'manual__2025-08-18T23:55:54.595255+00:00', '--job-id', '77', '--raw', '--subdir', 'DAGS_FOLDER/dbt_dag.py', '--cfg-path', '/tmp/tmpvhx7kmqp']
[2025-08-19T00:01:01.829+0000] {standard_task_runner.py:105} INFO - Job 77: Subtask dbt_run
[2025-08-19T00:01:01.880+0000] {task_command.py:467} INFO - Running <TaskInstance: dbt_workflow.dbt_run manual__2025-08-18T23:55:54.595255+00:00 [running]> on host 8700b4336131
[2025-08-19T00:01:01.953+0000] {taskinstance.py:3131} INFO - Exporting env vars: AIRFLOW_CTX_DAG_OWNER='***' AIRFLOW_CTX_DAG_ID='dbt_workflow' AIRFLOW_CTX_TASK_ID='dbt_run' AIRFLOW_CTX_EXECUTION_DATE='2025-08-18T23:55:54.595255+00:00' AIRFLOW_CTX_TRY_NUMBER='2' AIRFLOW_CTX_DAG_RUN_ID='manual__2025-08-18T23:55:54.595255+00:00'
[2025-08-19T00:01:01.954+0000] {logging_mixin.py:190} INFO - Task instance is in running state
[2025-08-19T00:01:01.955+0000] {logging_mixin.py:190} INFO -  Previous state of the Task instance: queued
[2025-08-19T00:01:01.955+0000] {logging_mixin.py:190} INFO - Current task name:dbt_run state:running start_date:2025-08-19 00:01:01.802112+00:00
[2025-08-19T00:01:01.956+0000] {logging_mixin.py:190} INFO - Dag name:dbt_workflow and current dag run status:running
[2025-08-19T00:01:01.956+0000] {taskinstance.py:731} INFO - ::endgroup::
[2025-08-19T00:01:01.957+0000] {subprocess.py:63} INFO - Tmp dir root location: /tmp
[2025-08-19T00:01:01.958+0000] {subprocess.py:75} INFO - Running command: ['/usr/bin/bash', '-c', 'cd /opt/***/dwh_project/snowflake_data_project && dbt run --profiles-dir /opt/***/dwh_project/snowflake_data_project/.dbt']
[2025-08-19T00:01:01.969+0000] {subprocess.py:86} INFO - Output:
[2025-08-19T00:01:04.336+0000] {subprocess.py:93} INFO - [0m00:01:04  Running with dbt=1.10.9
[2025-08-19T00:01:04.345+0000] {subprocess.py:93} INFO - [0m00:01:04  Encountered an error:
[2025-08-19T00:01:04.346+0000] {subprocess.py:93} INFO - Runtime Error
[2025-08-19T00:01:04.346+0000] {subprocess.py:93} INFO -   Could not find profile named 'snowflake_data_project'
[2025-08-19T00:01:07.487+0000] {local_task_job_runner.py:127} ERROR - Received SIGTERM. Terminating subprocesses
[2025-08-19T00:01:07.507+0000] {process_utils.py:132} INFO - Sending 15 to group 282. PIDs of all processes in the group: [284, 282]
[2025-08-19T00:01:07.516+0000] {process_utils.py:87} INFO - Sending the signal 15 to group 282
[2025-08-19T00:01:07.521+0000] {taskinstance.py:3092} ERROR - Received SIGTERM. Terminating subprocesses.
[2025-08-19T00:01:07.526+0000] {subprocess.py:104} INFO - Sending SIGTERM signal to process group
[2025-08-19T00:01:07.583+0000] {taskinstance.py:3310} ERROR - Task failed with exception
Traceback (most recent call last):
  File "/home/airflow/.local/lib/python3.12/site-packages/airflow/models/taskinstance.py", line 767, in _execute_task
    result = _execute_callable(context=context, **execute_callable_kwargs)
             ^^^^^^^^^^^^^^^^^^^^^^^^^^^^^^^^^^^^^^^^^^^^^^^^^^^^^^^^^^^^^
  File "/home/airflow/.local/lib/python3.12/site-packages/airflow/models/taskinstance.py", line 733, in _execute_callable
    return ExecutionCallableRunner(
           ^^^^^^^^^^^^^^^^^^^^^^^^
  File "/home/airflow/.local/lib/python3.12/site-packages/airflow/utils/operator_helpers.py", line 252, in run
    return self.func(*args, **kwargs)
           ^^^^^^^^^^^^^^^^^^^^^^^^^^
  File "/home/airflow/.local/lib/python3.12/site-packages/airflow/models/baseoperator.py", line 406, in wrapper
    return func(self, *args, **kwargs)
           ^^^^^^^^^^^^^^^^^^^^^^^^^^^
  File "/home/airflow/.local/lib/python3.12/site-packages/airflow/operators/bash.py", line 240, in execute
    result = self.subprocess_hook.run_command(
             ^^^^^^^^^^^^^^^^^^^^^^^^^^^^^^^^^
  File "/home/airflow/.local/lib/python3.12/site-packages/airflow/hooks/subprocess.py", line 91, in run_command
    for raw_line in iter(self.sub_process.stdout.readline, b""):
                    ^^^^^^^^^^^^^^^^^^^^^^^^^^^^^^^^^^^^^^^^^^^
  File "/home/airflow/.local/lib/python3.12/site-packages/airflow/models/taskinstance.py", line 3094, in signal_handler
    raise AirflowTaskTerminated("Task received SIGTERM signal")
airflow.exceptions.AirflowTaskTerminated: Task received SIGTERM signal
[2025-08-19T00:01:07.592+0000] {logging_mixin.py:190} INFO - Task instance in failure state
[2025-08-19T00:01:07.594+0000] {logging_mixin.py:190} INFO - Task start:2025-08-19 00:01:01.802112+00:00 end:2025-08-19 00:01:07.590974+00:00 duration:5.788862
[2025-08-19T00:01:07.595+0000] {logging_mixin.py:190} INFO - Task:<Task(BashOperator): dbt_run> dag:<DAG: dbt_workflow> dagrun:<DagRun dbt_workflow @ 2025-08-18 23:55:54.595255+00:00: manual__2025-08-18T23:55:54.595255+00:00, state:running, queued_at: 2025-08-18 23:55:54.612526+00:00. externally triggered: True>
[2025-08-19T00:01:07.596+0000] {logging_mixin.py:190} INFO - Failure caused by Task received SIGTERM signal
[2025-08-19T00:01:07.597+0000] {taskinstance.py:1225} INFO - Marking task as FAILED. dag_id=dbt_workflow, task_id=dbt_run, run_id=manual__2025-08-18T23:55:54.595255+00:00, execution_date=20250818T235554, start_date=20250819T000101, end_date=20250819T000107
[2025-08-19T00:01:07.616+0000] {taskinstance.py:340} INFO - ::group::Post task execution logs
[2025-08-19T00:01:07.666+0000] {process_utils.py:80} INFO - Process psutil.Process(pid=284, status='terminated', started='00:01:01') (284) terminated with exit code None
[2025-08-19T00:01:07.667+0000] {process_utils.py:80} INFO - Process psutil.Process(pid=282, status='terminated', exitcode=2, started='00:01:01') (282) terminated with exit code 2
[2025-08-19T00:01:07.668+0000] {local_task_job_runner.py:266} INFO - Task exited with return code 143
