[2025-08-18T23:55:41.418+0000] {local_task_job_runner.py:123} INFO - ::group::Pre task execution logs
[2025-08-18T23:55:41.435+0000] {taskinstance.py:2612} INFO - Dependencies all met for dep_context=non-requeueable deps ti=<TaskInstance: dbt_workflow.dbt_run manual__2025-08-18T23:46:49.032396+00:00 [queued]>
[2025-08-18T23:55:41.442+0000] {taskinstance.py:2612} INFO - Dependencies all met for dep_context=requeueable deps ti=<TaskInstance: dbt_workflow.dbt_run manual__2025-08-18T23:46:49.032396+00:00 [queued]>
[2025-08-18T23:55:41.443+0000] {taskinstance.py:2865} INFO - Starting attempt 2 of 2
[2025-08-18T23:55:41.457+0000] {taskinstance.py:2888} INFO - Executing <Task(BashOperator): dbt_run> on 2025-08-18 23:46:49.032396+00:00
[2025-08-18T23:55:41.465+0000] {warnings.py:112} WARNING - /home/***/.local/lib/python3.12/site-packages/***/task/task_runner/standard_task_runner.py:70: DeprecationWarning: This process (pid=63) is multi-threaded, use of fork() may lead to deadlocks in the child.
  pid = os.fork()

[2025-08-18T23:55:41.467+0000] {standard_task_runner.py:104} INFO - Running: ['***', 'tasks', 'run', 'dbt_workflow', 'dbt_run', 'manual__2025-08-18T23:46:49.032396+00:00', '--job-id', '74', '--raw', '--subdir', 'DAGS_FOLDER/dbt_dag.py', '--cfg-path', '/tmp/tmp4b3jxl_x']
[2025-08-18T23:55:41.468+0000] {standard_task_runner.py:72} INFO - Started process 73 to run task
[2025-08-18T23:55:41.469+0000] {standard_task_runner.py:105} INFO - Job 74: Subtask dbt_run
[2025-08-18T23:55:41.539+0000] {task_command.py:467} INFO - Running <TaskInstance: dbt_workflow.dbt_run manual__2025-08-18T23:46:49.032396+00:00 [running]> on host 8700b4336131
[2025-08-18T23:55:41.641+0000] {taskinstance.py:3131} INFO - Exporting env vars: AIRFLOW_CTX_DAG_OWNER='***' AIRFLOW_CTX_DAG_ID='dbt_workflow' AIRFLOW_CTX_TASK_ID='dbt_run' AIRFLOW_CTX_EXECUTION_DATE='2025-08-18T23:46:49.032396+00:00' AIRFLOW_CTX_TRY_NUMBER='2' AIRFLOW_CTX_DAG_RUN_ID='manual__2025-08-18T23:46:49.032396+00:00'
[2025-08-18T23:55:41.643+0000] {logging_mixin.py:190} INFO - Task instance is in running state
[2025-08-18T23:55:41.644+0000] {logging_mixin.py:190} INFO -  Previous state of the Task instance: queued
[2025-08-18T23:55:41.644+0000] {logging_mixin.py:190} INFO - Current task name:dbt_run state:running start_date:2025-08-18 23:55:41.436094+00:00
[2025-08-18T23:55:41.645+0000] {logging_mixin.py:190} INFO - Dag name:dbt_workflow and current dag run status:running
[2025-08-18T23:55:41.645+0000] {taskinstance.py:731} INFO - ::endgroup::
[2025-08-18T23:55:41.647+0000] {subprocess.py:63} INFO - Tmp dir root location: /tmp
[2025-08-18T23:55:41.648+0000] {subprocess.py:75} INFO - Running command: ['/usr/bin/bash', '-c', 'cd /opt/***/dwh_project/snowflake_data_project && dbt run']
[2025-08-18T23:55:41.663+0000] {subprocess.py:86} INFO - Output:
[2025-08-18T23:55:44.456+0000] {subprocess.py:93} INFO - Usage: dbt run [OPTIONS]
[2025-08-18T23:55:44.456+0000] {subprocess.py:93} INFO - Try 'dbt run -h' for help.
[2025-08-18T23:55:44.457+0000] {subprocess.py:93} INFO - 
[2025-08-18T23:55:44.457+0000] {subprocess.py:93} INFO - Error: Invalid value for '--profiles-dir': Path '/home/***/.dbt' does not exist.
[2025-08-18T23:55:44.696+0000] {subprocess.py:97} INFO - Command exited with return code 2
[2025-08-18T23:55:44.709+0000] {taskinstance.py:3310} ERROR - Task failed with exception
Traceback (most recent call last):
  File "/home/airflow/.local/lib/python3.12/site-packages/airflow/models/taskinstance.py", line 767, in _execute_task
    result = _execute_callable(context=context, **execute_callable_kwargs)
             ^^^^^^^^^^^^^^^^^^^^^^^^^^^^^^^^^^^^^^^^^^^^^^^^^^^^^^^^^^^^^
  File "/home/airflow/.local/lib/python3.12/site-packages/airflow/models/taskinstance.py", line 733, in _execute_callable
    return ExecutionCallableRunner(
           ^^^^^^^^^^^^^^^^^^^^^^^^
  File "/home/airflow/.local/lib/python3.12/site-packages/airflow/utils/operator_helpers.py", line 252, in run
    return self.func(*args, **kwargs)
           ^^^^^^^^^^^^^^^^^^^^^^^^^^
  File "/home/airflow/.local/lib/python3.12/site-packages/airflow/models/baseoperator.py", line 406, in wrapper
    return func(self, *args, **kwargs)
           ^^^^^^^^^^^^^^^^^^^^^^^^^^^
  File "/home/airflow/.local/lib/python3.12/site-packages/airflow/operators/bash.py", line 249, in execute
    raise AirflowException(
airflow.exceptions.AirflowException: Bash command failed. The command returned a non-zero exit code 2.
[2025-08-18T23:55:44.714+0000] {logging_mixin.py:190} INFO - Task instance in failure state
[2025-08-18T23:55:44.714+0000] {logging_mixin.py:190} INFO - Task start:2025-08-18 23:55:41.436094+00:00 end:2025-08-18 23:55:44.713602+00:00 duration:3.277508
[2025-08-18T23:55:44.715+0000] {logging_mixin.py:190} INFO - Task:<Task(BashOperator): dbt_run> dag:<DAG: dbt_workflow> dagrun:<DagRun dbt_workflow @ 2025-08-18 23:46:49.032396+00:00: manual__2025-08-18T23:46:49.032396+00:00, state:running, queued_at: 2025-08-18 23:46:49.050247+00:00. externally triggered: True>
[2025-08-18T23:55:44.716+0000] {logging_mixin.py:190} INFO - Failure caused by Bash command failed. The command returned a non-zero exit code 2.
[2025-08-18T23:55:44.716+0000] {taskinstance.py:1225} INFO - Marking task as FAILED. dag_id=dbt_workflow, task_id=dbt_run, run_id=manual__2025-08-18T23:46:49.032396+00:00, execution_date=20250818T234649, start_date=20250818T235541, end_date=20250818T235544
[2025-08-18T23:55:44.730+0000] {taskinstance.py:340} INFO - ::group::Post task execution logs
[2025-08-18T23:55:44.730+0000] {standard_task_runner.py:124} ERROR - Failed to execute job 74 for task dbt_run (Bash command failed. The command returned a non-zero exit code 2.; 73)
Traceback (most recent call last):
  File "/home/airflow/.local/lib/python3.12/site-packages/airflow/task/task_runner/standard_task_runner.py", line 117, in _start_by_fork
    ret = args.func(args, dag=self.dag)
          ^^^^^^^^^^^^^^^^^^^^^^^^^^^^^
  File "/home/airflow/.local/lib/python3.12/site-packages/airflow/cli/cli_config.py", line 49, in command
    return func(*args, **kwargs)
           ^^^^^^^^^^^^^^^^^^^^^
  File "/home/airflow/.local/lib/python3.12/site-packages/airflow/utils/cli.py", line 115, in wrapper
    return f(*args, **kwargs)
           ^^^^^^^^^^^^^^^^^^
  File "/home/airflow/.local/lib/python3.12/site-packages/airflow/cli/commands/task_command.py", line 483, in task_run
    task_return_code = _run_task_by_selected_method(args, _dag, ti)
                       ^^^^^^^^^^^^^^^^^^^^^^^^^^^^^^^^^^^^^^^^^^^^
  File "/home/airflow/.local/lib/python3.12/site-packages/airflow/cli/commands/task_command.py", line 256, in _run_task_by_selected_method
    return _run_raw_task(args, ti)
           ^^^^^^^^^^^^^^^^^^^^^^^
  File "/home/airflow/.local/lib/python3.12/site-packages/airflow/cli/commands/task_command.py", line 341, in _run_raw_task
    return ti._run_raw_task(
           ^^^^^^^^^^^^^^^^^
  File "/home/airflow/.local/lib/python3.12/site-packages/airflow/utils/session.py", line 97, in wrapper
    return func(*args, session=session, **kwargs)
           ^^^^^^^^^^^^^^^^^^^^^^^^^^^^^^^^^^^^^^
  File "/home/airflow/.local/lib/python3.12/site-packages/airflow/models/taskinstance.py", line 3004, in _run_raw_task
    return _run_raw_task(
           ^^^^^^^^^^^^^^
  File "/home/airflow/.local/lib/python3.12/site-packages/airflow/models/taskinstance.py", line 273, in _run_raw_task
    TaskInstance._execute_task_with_callbacks(
  File "/home/airflow/.local/lib/python3.12/site-packages/airflow/models/taskinstance.py", line 3158, in _execute_task_with_callbacks
    result = self._execute_task(context, task_orig)
             ^^^^^^^^^^^^^^^^^^^^^^^^^^^^^^^^^^^^^^
  File "/home/airflow/.local/lib/python3.12/site-packages/airflow/models/taskinstance.py", line 3182, in _execute_task
    return _execute_task(self, context, task_orig)
           ^^^^^^^^^^^^^^^^^^^^^^^^^^^^^^^^^^^^^^^
  File "/home/airflow/.local/lib/python3.12/site-packages/airflow/models/taskinstance.py", line 767, in _execute_task
    result = _execute_callable(context=context, **execute_callable_kwargs)
             ^^^^^^^^^^^^^^^^^^^^^^^^^^^^^^^^^^^^^^^^^^^^^^^^^^^^^^^^^^^^^
  File "/home/airflow/.local/lib/python3.12/site-packages/airflow/models/taskinstance.py", line 733, in _execute_callable
    return ExecutionCallableRunner(
           ^^^^^^^^^^^^^^^^^^^^^^^^
  File "/home/airflow/.local/lib/python3.12/site-packages/airflow/utils/operator_helpers.py", line 252, in run
    return self.func(*args, **kwargs)
           ^^^^^^^^^^^^^^^^^^^^^^^^^^
  File "/home/airflow/.local/lib/python3.12/site-packages/airflow/models/baseoperator.py", line 406, in wrapper
    return func(self, *args, **kwargs)
           ^^^^^^^^^^^^^^^^^^^^^^^^^^^
  File "/home/airflow/.local/lib/python3.12/site-packages/airflow/operators/bash.py", line 249, in execute
    raise AirflowException(
airflow.exceptions.AirflowException: Bash command failed. The command returned a non-zero exit code 2.
[2025-08-18T23:55:44.775+0000] {local_task_job_runner.py:266} INFO - Task exited with return code 1
[2025-08-18T23:55:44.805+0000] {taskinstance.py:3900} INFO - 0 downstream tasks scheduled from follow-on schedule check
[2025-08-18T23:55:44.810+0000] {local_task_job_runner.py:245} INFO - ::endgroup::
